Workbook

Sheet Summary
A1: LoanLens AI
A2: Development Task Tracker
A4: FocusNext 2026 — Team "RAG to Riches"
A5: Khavya Sakthivel & Sukumar Dhandapani (Development) · Souvik Das (QA) — updated 2026-10-24 (identity, credit, residency and duplicate checks added)
A6: Prepared 2026-09-11 · Target: basic MVP in 4 weeks (Week 1 core build, Weeks 2-4 hardening & refinement)
A8: How to use this tracker
A9: Open the Tasks tab. Filter or sort by Section/Status, put your name in the Owner column for anything you're picking up, and update Status as you go. Sections 13-15 are new feature ideas from pain-point research (Rovo AI, 2026-09-11) — not yet scoped into a sprint, listed here so nothing gets lost; tackle them after the core MVP (Sections 1-12) is demo-ready.
A11: Overall progress
A12: Completed | B12: In Progress | C12: Not Started | D12: Total
A13: =COUNTIF(Tasks!$D$2:$D$209,"Completed") | B13: =COUNTIF(Tasks!$D$2:$D$209,"In Progress") | C13: =COUNTIF(Tasks!$D$2:$D$209,"Not Started") | D13: =SUM(A13:C13)
A16: By section
A17: Section | B17: Completed | C17: In Progress | D17: Not Started | E17: Total
A18: 1. Environment & Scaffolding | B18: =COUNTIFS(Tasks!$B$2:$B$209,$A18,Tasks!$D$2:$D$209,"Completed") | C18: =COUNTIFS(Tasks!$B$2:$B$209,$A18,Tasks!$D$2:$D$209,"In Progress") | D18: =COUNTIFS(Tasks!$B$2:$B$209,$A18,Tasks!$D$2:$D$209,"Not Started") | E18: =SUM(B18:D18)
A19: 2. Authentication & Access Control | B19: =COUNTIFS(Tasks!$B$2:$B$209,$A19,Tasks!$D$2:$D$209,"Completed") | C19: =COUNTIFS(Tasks!$B$2:$B$209,$A19,Tasks!$D$2:$D$209,"In Progress") | D19: =COUNTIFS(Tasks!$B$2:$B$209,$A19,Tasks!$D$2:$D$209,"Not Started") | E19: =SUM(B19:D19)
A20: 3. Data Model & Database (MongoDB) | B20: =COUNTIFS(Tasks!$B$2:$B$209,$A20,Tasks!$D$2:$D$209,"Completed") | C20: =COUNTIFS(Tasks!$B$2:$B$209,$A20,Tasks!$D$2:$D$209,"In Progress") | D20: =COUNTIFS(Tasks!$B$2:$B$209,$A20,Tasks!$D$2:$D$209,"Not Started") | E20: =SUM(B20:D20)
A21: 4. Document Intelligence (OCR / AI Extraction) | B21: =COUNTIFS(Tasks!$B$2:$B$209,$A21,Tasks!$D$2:$D$209,"Completed") | C21: =COUNTIFS(Tasks!$B$2:$B$209,$A21,Tasks!$D$2:$D$209,"In Progress") | D21: =COUNTIFS(Tasks!$B$2:$B$209,$A21,Tasks!$D$2:$D$209,"Not Started") | E21: =SUM(B21:D21)
A22: 5. Cross-Verification Engine | B22: =COUNTIFS(Tasks!$B$2:$B$209,$A22,Tasks!$D$2:$D$209,"Completed") | C22: =COUNTIFS(Tasks!$B$2:$B$209,$A22,Tasks!$D$2:$D$209,"In Progress") | D22: =COUNTIFS(Tasks!$B$2:$B$209,$A22,Tasks!$D$2:$D$209,"Not Started") | E22: =SUM(B22:D22)
A23: 6. RAG Assistant (Conversational Q&A) | B23: =COUNTIFS(Tasks!$B$2:$B$209,$A23,Tasks!$D$2:$D$209,"Completed") | C23: =COUNTIFS(Tasks!$B$2:$B$209,$A23,Tasks!$D$2:$D$209,"In Progress") | D23: =COUNTIFS(Tasks!$B$2:$B$209,$A23,Tasks!$D$2:$D$209,"Not Started") | E23: =SUM(B23:D23)
A24: 7. Frontend — Screens & Navigation | B24: =COUNTIFS(Tasks!$B$2:$B$209,$A24,Tasks!$D$2:$D$209,"Completed") | C24: =COUNTIFS(Tasks!$B$2:$B$209,$A24,Tasks!$D$2:$D$209,"In Progress") | D24: =COUNTIFS(Tasks!$B$2:$B$209,$A24,Tasks!$D$2:$D$209,"Not Started") | E24: =SUM(B24:D24)
A25: 8. Synthetic Demo Data | B25: =COUNTIFS(Tasks!$B$2:$B$209,$A25,Tasks!$D$2:$D$209,"Completed") | C25: =COUNTIFS(Tasks!$B$2:$B$209,$A25,Tasks!$D$2:$D$209,"In Progress") | D25: =COUNTIFS(Tasks!$B$2:$B$209,$A25,Tasks!$D$2:$D$209,"Not Started") | E25: =SUM(B25:D25)
A26: 9. WhatsApp Integration | B26: =COUNTIFS(Tasks!$B$2:$B$209,$A26,Tasks!$D$2:$D$209,"Completed") | C26: =COUNTIFS(Tasks!$B$2:$B$209,$A26,Tasks!$D$2:$D$209,"In Progress") | D26: =COUNTIFS(Tasks!$B$2:$B$209,$A26,Tasks!$D$2:$D$209,"Not Started") | E26: =SUM(B26:D26)
A27: 10. Hosting & Deployment | B27: =COUNTIFS(Tasks!$B$2:$B$209,$A27,Tasks!$D$2:$D$209,"Completed") | C27: =COUNTIFS(Tasks!$B$2:$B$209,$A27,Tasks!$D$2:$D$209,"In Progress") | D27: =COUNTIFS(Tasks!$B$2:$B$209,$A27,Tasks!$D$2:$D$209,"Not Started") | E27: =SUM(B27:D27)
A28: 11. Testing & QA | B28: =COUNTIFS(Tasks!$B$2:$B$209,$A28,Tasks!$D$2:$D$209,"Completed") | C28: =COUNTIFS(Tasks!$B$2:$B$209,$A28,Tasks!$D$2:$D$209,"In Progress") | D28: =COUNTIFS(Tasks!$B$2:$B$209,$A28,Tasks!$D$2:$D$209,"Not Started") | E28: =SUM(B28:D28)
A29: 12. Documentation | B29: =COUNTIFS(Tasks!$B$2:$B$209,$A29,Tasks!$D$2:$D$209,"Completed") | C29: =COUNTIFS(Tasks!$B$2:$B$209,$A29,Tasks!$D$2:$D$209,"In Progress") | D29: =COUNTIFS(Tasks!$B$2:$B$209,$A29,Tasks!$D$2:$D$209,"Not Started") | E29: =SUM(B29:D29)
... A37: 20. Policy Documents & Policy Page | B37: =COUNTIFS(Tasks!$B$2:$B$209,$A37,Tasks!$D$2:$D$209,"Completed") | C37: =COUNTIFS(Tasks!$B$2:$B$209,$A37,Tasks!$D$2:$D$209,"In Progress") | D37: =COUNTIFS(Tasks!$B$2:$B$209,$A37,Tasks!$D$2:$D$209,"Not Started") | E37: =SUM(B37:D37)

Sheet Tasks
A1: # | B1: Section | C1: Task | D1: Status | E1: Owner | F1: Notes
A2: 1 | B2: 1. Environment & Scaffolding | C2: Backend scaffold — Express + Mongoose + dotenv + CORS | D2: Completed | F2: backend/src/index.js
A3: 2 | B3: 1. Environment & Scaffolding | C3: Frontend scaffold — Expo React Native app (web-enabled) | D3: Completed | F3: frontend/App.js
A4: 3 | B4: 1. Environment & Scaffolding | C4: Environment variable templates (.env.example) | D4: Completed | F4: Both backend/ and frontend/
A5: 4 | B5: 1. Environment & Scaffolding | C5: Render Blueprint config (backend web service + frontend static site) | D5: Completed | F5: render.yaml
A6: 5 | B6: 1. Environment & Scaffolding | C6: GitHub repo + Codespaces-compatible workflow | D6: Completed | F6: No local Node needed — README 'No-local-Node workflow'
A7: 6 | B7: 2. Authentication & Access Control | C7: JWT login endpoint (POST /auth/login) | D7: Completed | F7: backend/src/routes/auth.js
A8: 7 | B8: 2. Authentication & Access Control | C8: Auth middleware — token verification on protected routes | D8: Completed | F8: backend/src/middleware/auth.js
A9: 8 | B9: 2. Authentication & Access Control | C9: Officer vs. borrower role-based data scoping | D9: Completed | F9: Officers see all applications; borrowers see only their own — routes/applications.js
A10: 9 | B10: 2. Authentication & Access Control | C10: Login screen + session persistence (AsyncStorage) | D10: Completed | F10: LoginScreen.js, AuthContext.js
A11: 10 | B11: 2. Authentication & Access Control | C11: Self-service registration (POST /auth/register) | D11: Completed | F11: No email verification — synthetic-data demo, not real bank onboarding. Lets teammates spin up their own officer/borrower test accounts instead of needing seeded ones
A12: 11 | B12: 2. Authentication & Access Control | C12: Password reset | D12: Not Started | F12: Out of scope for demo
A13: 12 | B13: 3. Data Model & Database (MongoDB) | C13: MongoDB Atlas connection (Mongoose) | D13: Completed | F13: backend/src/config/db.js
... A25: 24 | B25: 4. Document Intelligence (OCR / AI Extraction) | C25: Claude vision classify + extract (single API call, no separate OCR service) | D25: Completed | F25: services/extraction.js
A26: 25 | B26: 4. Document Intelligence (OCR / AI Extraction) | C26: Consumer document types — pay stub, W-2, bank statement, driver's license | D26: Completed
A27: 26 | B27: 4. Document Intelligence (OCR / AI Extraction) | C27: Small-business document types — tax return, personal financial statement, business license, ownership disclosure | D27: Completed | F27: extraction.js prompt + fields extended
A28: 27 | B28: 4. Document Intelligence (OCR / AI Extraction) | C28: Document upload endpoint (multer, 10MB limit) | D28: Completed | F28: routes/documents.js
A29: 28 | B29: 4. Document Intelligence (OCR / AI Extraction) | C29: Uploaded file bytes stored (fileData/mimeType on Document) | D29: Completed | F29: Previously the temp file was deleted right after extraction with no copy kept anywhere — there was no way to check what you'd actually uploaded once processed
A30: 29 | B30: 4. Document Intelligence (OCR / AI Extraction) | C30: GET /documents/:id/file — preview/download the original upload | D30: Completed | F30: Served inline with correct Content-Type; excluded from the main application/list fetch responses (.select('-fileData')) so those payloads don't balloon with binary data
A31: 30 | B31: 4. Document Intelligence (OCR / AI Extraction) | C31: DELETE /documents/:id — remove a document outright | D31: Completed | F31: Distinct from a targeted re-upload (which supersedes and keeps the old one for audit trail) — this actually removes it; the required item goes back to 'missing'
A32: 31 | B32: 4. Document Intelligence (OCR / AI Extraction) | C32: Confidence scoring + low-confidence to human review routing | D32: Completed | F32: services/verification.js
A33: 32 | B33: 4. Document Intelligence (OCR / AI Extraction) | C33: Extraction accuracy tuning against real-world-style documents | D33: Not Started | F33: Only validated against synthetic generated images so far
A34: 33 | B34: 4. Document Intelligence (OCR / AI Extraction) | C34: MOCK_AI bypass — canned extraction results, no Anthropic API call | D34: Completed | F34: services/mockFixtures.js + extraction.js/rag.js. Added when ANTHROPIC_API_KEY hit a zero credit-balance error blocking all testing — lets verification/live-exception/status-transition testing continue independent of API billing state. Off by default; must not be left on for the real demo
A35: 34 | B35: 5. Cross-Verification Engine | C35: Deterministic rule engine (not LLM — explainable/auditable) | D35: Completed | F35: services/verification.js
A36: 35 | B36: 5. Cross-Verification Engine | C36: Name match check | D36: Completed
A37: 36 | B37: 5. Cross-Verification Engine | C37: Income match check (5% tolerance) | D37: Completed
A38: 37 | B38: 5. Cross-Verification Engine | C38: Employer match check | D38: Completed
A39: 38 | B39: 5. Cross-Verification Engine | C39: SSN (last 4) match check | D39: Completed
A40: 39 | B40: 5. Cross-Verification Engine | C40: Business name / DBA match check | D40: Completed | F40: Demonstrates the entity-name-mismatch pattern found in production loan-servicing tickets
A41: 40 | B41: 5. Cross-Verification Engine | C41: Annual business revenue match check | D41: Completed
A42: 41 | B42: 5. Cross-Verification Engine | C42: Missing-document detection | D42: Completed | F42: missingDocuments() in verification.js
A43: 42 | B43: 5. Cross-Verification Engine | C43: Requested-amount affordability check (auto-loan, personal-loan, small-business-loan) | D43: Completed | F43: New — compares requestedAmount against a simplified income/revenue-based estimate; flags as Warning, never auto-declines. Not a real credit/DSCR calculation
A44: 43 | B44: 5. Cross-Verification Engine | C44: Warning-level flags surface at the application list level, not just inside document detail | D44: Completed | F44: Fixed today — routes/documents.js previously only bumped application status to Needs Review on a hard Mismatch, so an affordability warning was invisible in the officer's list view
A45: 44 | B45: 5. Cross-Verification Engine | C45: US currency formatting fixed regardless of server/browser locale | D45: Completed | F45: toLocaleString() was rendering $3,40,000-style grouping on non-US locales; forced to 'en-US' across backend and frontend
A46: 45 | B46: 5. Cross-Verification Engine | C46: One-click 'request missing document' email to borrower | D46: Completed | F46: Superseded by the richer in-app live-exception + targeted self-service re-upload flow — see Section 13. No email/SMS needed; the borrower sees and fixes it directly in the app
A47: 46 | B47: 6. RAG Assistant (Conversational Q&A) | C47: Policy corpus grounding (full corpus in context — no vector DB yet) | D47: Completed | F47: services/rag.js
A48: 47 | B48: 6. RAG Assistant (Conversational Q&A) | C48: Citation / source attribution on every answer | D48: Completed
A49: 48 | B49: 6. RAG Assistant (Conversational Q&A) | C49: Role-aware answers (officer vs. borrower) | D49: Completed
A50: 49 | B50: 6. RAG Assistant (Conversational Q&A) | C50: Refusal behavior for out-of-corpus questions (no invented rates/policy) | D50: Completed | F50: Validated in data/seed/test-questions.md
A51: 50 | B51: 6. RAG Assistant (Conversational Q&A) | C51: Small-business loan Q&A coverage | D51: Completed | F51: test-questions.md items 19-23
...

Sheet Test Scenarios
A1: # | B1: Feature Area | C1: Test Scenario | D1: Steps to Test | E1: Expected Result | F1: Why This Matters (Use Case & Impact) | G1: Verified So Far
A2: 1 | B2: Affordability check | C2: Auto/personal loan requested amount within the estimated affordable range | D2: Upload a pay stub where documented income comfortably supports the requested amount. | E2: 'Requested amount vs. affordability' check shows status Match — no flag. | F2: Confirms the check doesn't cry wolf on ordinary, reasonable requests — false positives would erode officer trust in every other flag the system raises. | G2: Yes — executed directly against verification.js with real inputs (see chat transcript)
A3: 2 | B3: Affordability check | C3: Auto/personal loan requested amount exceeds the estimate | D3: Upload a pay stub where documented income is well below what the requested amount implies. | E3: Status Warning (not a hard decline), names the multiple over (e.g. '3.1x'), suggests checking for a data-entry error, and the application still requires officer sign-off. | F3: This is the gap that existed before today's session: nothing previously checked requested amount against income at all. Officers can now triage oversized asks instead of discovering them deep in manual underwriting. | G3: Yes — executed directly against verification.js with real inputs (see chat transcript)
A4: 3 | B4: Affordability check | C4: Combined income mismatch + oversized request (worse-case) | D4: Pay stub shows both a different income than stated AND a requested amount unaffordable even at the (lower) documented income. | E4: Both checks fire independently; overall status is 'fail' (hard mismatch outranks a warning) — the more serious problem wins the overall severity. | F4: Confirms severity ranking is sane: a data conflict (documents disagree) is treated as more serious than a disproportionate-but-consistent request, so officers aren't misled about which case is more urgent. | G4: Yes — executed directly against verification.js with real inputs (see chat transcript)
A5: 4 | B5: Affordability check | C5: Extreme, isolated oversized request ($500/mo income, $5,000,000 requested) | D5: Income confirmed correct and consistent; only the requested amount is absurd. | E5: Overall status is 'needs-review', not 'fail' — distinguishing 'plausible but oversized' from 'documents disagree'. Explanation states the request is ~617x the affordable estimate. | F5: This is the exact scenario raised in planning: proves the system never auto-declines, always routes to a human, and gives the officer enough context (the multiple) to spot a likely typo instantly instead of investigating from scratch. | G5: Yes — executed directly against verification.js with real inputs (see chat transcript)
A6: 5 | B6: Affordability check | C6: Small-business flagship scenario (Whitfield & Co. Bakery LLC) | D6: Run the seeded small-business application: tax return shows $275,400 revenue vs. $340,000 stated, business license shows a different legal name, and $110,000 is requested. | E6: Three independent flags appear together — revenue mismatch, business-name mismatch, and affordability (~1.3x over) — each with its own plain-English explanation. | F6: This is the demo's core evidence that the engine catches the real, evidence-backed pain points (entity-name mismatches, revenue verification) found in production loan-servicing research, not hypothetical ones. | G6: Yes — executed directly against verification.js with real inputs (see chat transcript)
A7: 6 | B7: Data quality | C7: US currency formatting is locale-independent | D7: Run any check that renders a dollar amount on a machine/browser set to a non-US locale. | E7: Amounts render as '$340,000' (US grouping), never '$3,40,000' or similar. | F7: Caught during this session's own testing — would have looked broken live in front of judges depending on whoever's laptop or browser locale was in use, undermining credibility for reasons having nothing to do with the actual feature. | G7: Yes — executed directly against verification.js with real inputs (see chat transcript)
A8: 7 | B8: Live exception flow | C8: A flagged document appears in the borrower's/officer's 'Action needed' list | D8: Upload a document that fails a check (e.g. Jordan Rivera's pay stub, planted income mismatch). | E8: Documents tab shows an 'Action needed' card naming the specific issue in plain language, with a Re-upload button. | F8: Replaces 'the flag exists somewhere in a Verification tab, hope someone notices' with one obvious, actionable place — this is the core of the 'live exception' pitch. | G8: Partial — core logic simulated in Node standalone; full Express+MongoDB route not executed (no local .env/API key in this environment)
A9: 8 | B9: Live exception flow | C9: Targeted re-upload resolves exactly one exception | D9: Tap Re-upload on one flagged item and upload a corrected document. | E9: That exception disappears from the Action needed list; other open exceptions (if any) are untouched. | F9: This is the 'minutes not days' claim made concrete — no email, no waiting for an officer to notice, no restarting the application. | G9: Partial — core logic simulated in Node standalone; full Express+MongoDB route not executed (no local .env/API key in this environment)
A10: 9 | B10: Live exception flow | C10: Wrong file type caught immediately during a targeted fix | D10: While fixing a specific required item (e.g. Driver's License), upload an unrelated document type (e.g. a bank statement). | E10: A 'Document type' mismatch appears immediately, naming both the expected and actual type — not a silent or confusing failure. | F10: Prevents a second round of 'document ping-pong' from being reintroduced by the fix mechanism itself — the applicant knows right away, not after another review cycle. | G10: Yes — executed directly against verification.js with real inputs (see chat transcript)
A11: 10 | B11: Live exception flow | C11: A wrong-type attempt doesn't linger as an orphaned exception | D11: Immediately follow the previous scenario with the correct document type for that same slot. | E11: The earlier wrong-type attempt is superseded (marked historical), not left behind as a second, permanent exception with no way to resolve it. | F11: This was an actual bug found and fixed during this session's own testing before shipping — without the fix, a single wrong upload would have permanently cluttered the exception list with no way to clear it. | G11: Yes — executed directly against verification.js with real inputs (see chat transcript)
A12: 11 | B12: Live exception flow | C12: Application status self-heals once every exception clears | D12: Resolve the last open exception on an application that was in 'Needs Review'. | E12: Application status automatically returns to 'Submitted' — no officer action required to remove a flag that no longer applies. | F12: Closes the loop end-to-end: today, even after a borrower fixes something, an officer typically has to notice and manually clear the flag. This makes the fix instantly visible everywhere the status is shown. | G12: Not yet — implemented in code, needs a live click-through once real MongoDB/Claude credentials exist
A13: 12 | B13: Live exception flow | C13: Superseded documents are preserved for audit but hidden from the active view | D13: After a targeted fix, open 'Show document history' on the Documents tab. | E13: The old (fixed) document appears there, clearly marked 'Superseded', separate from the current, active document list. | F13: Keeps the 'complete audit trail' claim in the original pitch true even as documents get corrected — nothing is silently deleted. | G13: Not yet — implemented in code, needs a live click-through once real MongoDB/Claude credentials exist
... A49: 48 | B49: Residency | C49: A visa that ends before the loan can only be approved as an exception (Lakshmi Pillai) | D49: Open Lakshmi Pillai > Decision, run the checks; then refer and have the underwriter approve waiving "residency" with a condition. | E49: "Residency status covers the loan term" is Not Met (visa to 2028-06-30, 36-month term to 2029-10); the officer cannot approve; the underwriter can, with compensating factors and a condition. | F49: Shows a practical residency rule without ever verifying citizenship against a government source. | G49: Yes — unit tests (including the underwriter approval); previewed in the browser against a mock API

Sheet Proposal vs Built
A1: Proposal promise | B1: Status | C1: What exists today | D1: Gap / next step | E1: Tracker section
A2: Extract data and cross-verify name, SSN, income, address | B2: Built, with gaps | C2: Name, income, employer, SSN last-4, business name, revenue, plus cross-document deposit and payroll-math checks | D2: Address is not compared; SSN is last-4 only | E2: 5, 19
A3: Confidence scoring with human-in-the-loop routing | B3: Built | C3: Low-confidence extractions are flagged for review, never guessed | D3: — | E3: 4
A4: Exceptions dashboard | B4: Built | C4: Action Needed list and page; flags show in the application list | D4: — | E4: 13
A5: Officer is the final approver | B5: Built | C5: Loan officer and underwriter decision workflow with an audit trail | D5: Notifications, appeals, real minimum credit scores | E5: 18
A6: RAG Q&A with citations for officers and borrowers (web) | B6: Built, not true RAG | C6: Policy corpus grounded answers with citations; chat also navigates to pages | D6: Vector search and per-tenant retrieval; policy page with highlighting | E6: 6, 20
A7: RAG on WhatsApp | B7: Not started | C7: — | D7: Webhook, routing into the assistant, outbound replies | E7: 9
A8: Missing-document detection with one-click borrower email | B8: Detection built | C8: In-app self-service re-upload replaces the email | D8: Email notification not built | E8: 13, 19
A9: "Binder dump": auto-split and classify large mixed PDFs (200–500 pages) | B9: Not built | C9: One upload is one document | D9: Page splitting, page-level classification, progress | E9: 19
A10: TILA / RESPA disclosure-timing checks | B10: Not built | C10: — | D10: Rules and data model | E10: 19
A11: MISMO JSON output for LOS integration | B11: Not built | C11: — | D11: Phase 3 of the submission | E11: 19
A12: Complete audit trail of every extraction and decision | B12: Partial | C12: Decisions, referrals and credit-score entries are logged; superseded documents kept | D12: Log uploads and extractions | E12: 18, 19
... A17: Added beyond the proposal | B17: Extra | C17: Small-business vertical, self-service live exceptions, payroll-math and deposit checks, affordability warning, underwriter exception workflow, mock-AI mode | D17: Lead the pitch with the exception and fraud-signal story | E17: 5, 13, 18
